<?xml version="1.0"?>
<robot name="DexterousHand">
    <material name="default">
        <color rgba="0.4 0.75 1 0.6"/>
    </material>


    <link name="world"/>
    <joint name="world_to_palm" type="fixed">
        <parent link="world"/>
        <child link="palm"/>
        <origin xyz="0 0 0" rpy="0 0 0"/>
    </joint>
    <link name="palm">
        <inertial>
            <origin xyz="0 0 0.0436" rpy="0 0 0"/>
            <mass value="0.1289964082176"/>
            <inertia ixx="0.00012260850608266445" ixy="0.0" ixz="0.0" iyy="6.25580981292073e-05" iyz="0.0" izz="6.25580981292073e-05"/>
        </inertial>
        <visual>
            <origin xyz="0 0 0.0436" rpy="1.5708 0 1.5708"/>
            <geometry>
                <cylinder radius="0.0436" length="0.0216"/>
            </geometry>
            <material name="default"/>
        </visual>
        <collision>
            <origin xyz="0 0 0.0436" rpy="1.5708 0 1.5708"/>
            <geometry>
                <cylinder radius="0.0436" length="0.0216"/>
            </geometry>
        </collision>
    </link>

    
    <joint name="thumb_joint1" type="revolute">
        <parent link="palm"/>
        <child link="thumb_base"/>
        <origin xyz="0.0193 0.0 0.023" rpy="-0.7854 1.5708 -0.7854"/>
        <axis xyz="0.0 0.0 1.0"/>
        <limit lower="-1.0472" upper="1.0472" effort="1.0" velocity="1.0"/>
    </joint>

    <link name="thumb_base"></link>

    <joint name="thumb_joint2" type="revolute">
        <parent link="thumb_base"/>
        <child link="thumb_proximal"/>
        <origin xyz="0 0 0" rpy="0 0 0"/>
        <axis xyz="0.0 1.0 0.0"/>
        <limit lower="-1.0472" upper="0.6109" effort="1.0" velocity="1.0"/>
    </joint>

    <link name="thumb_proximal">
        <inertial>
            <origin xyz="0 0 0.0229" rpy="0 0 0"/>
            <mass value="0.0167827790592"/>
            <inertia ixx="3.4230715595112964e-06" ixy="0.0" ixz="0.0" iyy="3.4230715595112964e-06" iyz="0.0" izz="9.787716747325442e-07"/>
        </inertial>
        <visual>
            <origin xyz="0 0 0.0229" rpy="0 0 0"/>
            <geometry>
                <cylinder radius="0.0108" length="0.0242"/>
            </geometry>
            <material name="default"/>
        </visual>
        <visual>
            <origin xyz="0 0 0.0108" rpy="0 0 0"/>
            <geometry>
                <sphere radius="0.0108"/>
            </geometry>
            <material name="default"/>
        </visual>
        <visual>
            <origin xyz="0 0 0.035" rpy="0 0 0"/>
            <geometry>
                <sphere radius="0.0108"/>
            </geometry>
            <material name="default"/>
        </visual>
        <collision>
            <origin xyz="0 0 0.0229" rpy="0 0 0"/>
            <geometry>
                <cylinder radius="0.0108" length="0.0242"/>
            </geometry>
        </collision>
        <collision>
            <origin xyz="0 0 0.0108" rpy="0 0 0"/>
            <geometry>
                <sphere radius="0.0108"/>
            </geometry>
        </collision>
        <collision>
            <origin xyz="0 0 0.035" rpy="0 0 0"/>
            <geometry>
                <sphere radius="0.0108"/>
            </geometry>
        </collision>
    </link>

    <joint name="thumb_joint3" type="revolute">
        <parent link="thumb_proximal"/>
        <child link="thumb_knuckle"/>
        <origin xyz="0 0 0.0458" rpy="0 0 0"/> 
        <axis xyz="1 0 0"/>
        <limit lower="0.0" upper="0.0" effort="1.0" velocity="1.0"/>
    </joint>

    <link name="thumb_knuckle"></link>

    <joint name="thumb_joint4" type="revolute">
        <parent link="thumb_knuckle"/>
        <child link="thumb_middle"/>
        <origin xyz="0 0 0" rpy="0 0 0"/> 
        <axis xyz="0 1 0"/>
        <limit lower="0.0" upper="0.0" effort="1.0" velocity="1.0"/>
    </joint>

    <link name="thumb_middle">
    </link>

    <joint name="thumb_joint5" type="revolute">
        <parent link="thumb_middle"/>
        <child link="thumb_distal"/>
        <origin xyz="0 0 0.0" rpy="0 0 0"/> 
        <axis xyz="0 1 0"/>
        <limit lower="-1.7453" upper="0.0" effort="1.0" velocity="1.0"/>
    </joint>

    <link name="thumb_distal">
        <inertial>
            <origin xyz="0 0 0.025" rpy="0 0 0"/>
            <mass value="0.018321811200000003"/>
            <inertia ixx="4.351308014592001e-06" ixy="0.0" ixz="0.0" iyy="4.351308014592001e-06" iyz="0.0" izz="1.0685280291840003e-06"/>
        </inertial>
        <visual>
            <origin xyz="0 0 0.025" rpy="0 0 0"/>
            <geometry>
                <cylinder radius="0.0108" length="0.0284"/>
            </geometry>
            <material name="default"/>
        </visual>
        <visual>
            <origin xyz="0 0 0.0108" rpy="0 0 0"/>
            <geometry>
                <sphere radius="0.0108"/>
            </geometry>
            <material name="default"/>
        </visual>
        <visual>
            <origin xyz="0 0 0.0392" rpy="0 0 0"/>
            <geometry>
                <sphere radius="0.0108"/>
            </geometry>
            <material name="default"/>
        </visual>
        <collision>
            <origin xyz="0 0 0.025" rpy="0 0 0"/>
            <geometry>
                <cylinder radius="0.0108" length="0.0284"/>
            </geometry>
        </collision>
        <collision>
            <origin xyz="0 0 0.0108" rpy="0 0 0"/>
            <geometry>
                <sphere radius="0.0108"/>
            </geometry>
        </collision>
        <collision>
            <origin xyz="0 0 0.0392" rpy="0 0 0"/>
            <geometry>
                <sphere radius="0.0108"/>
            </geometry>
        </collision>
    </link>

    
    <joint name="index_joint1" type="revolute">
        <parent link="palm"/>
        <child link="index_knuckle"/>
        <origin xyz="-0.0016 0.0285 0.0777" rpy="0 0 0"/>
        <axis xyz="1 0 0"/>
        <limit lower="0.0" upper="0.0" effort="1.0" velocity="1.0"/>
    </joint>

    <link name="index_knuckle"></link>

    <joint name="index_joint2" type="revolute">
        <parent link="index_knuckle"/>
        <child link="index_proximal"/>
        <origin xyz="0 0 0" rpy="0 0 0"/>
        <axis xyz="0 1 0"/>
        <limit lower="0.0" upper="1.5708" effort="1.0" velocity="1.0"/>
    </joint>

    <link name="index_proximal">
        <inertial>
            <origin xyz="0 0 0.0229" rpy="0 0 0"/>
            <mass value="0.0167827790592"/>
            <inertia ixx="3.4230715595112964e-06" ixy="0.0" ixz="0.0" iyy="3.4230715595112964e-06" iyz="0.0" izz="9.787716747325442e-07"/>
        </inertial>
        <visual>
            <origin xyz="0 0 0.0229" rpy="0 0 0"/>
            <geometry>
                <cylinder radius="0.0108" length="0.0242"/>
            </geometry>
            <material name="default"/>
        </visual>
        <visual>
            <origin xyz="0 0 0.0108" rpy="0 0 0"/>
            <geometry>
                <sphere radius="0.0108"/>
            </geometry>
            <material name="default"/>
        </visual>
        <visual>
            <origin xyz="0 0 0.035" rpy="0 0 0"/>
            <geometry>
                <sphere radius="0.0108"/>
            </geometry>
            <material name="default"/>
        </visual>
        <collision>
            <origin xyz="0 0 0.0229" rpy="0 0 0"/>
            <geometry>
                <cylinder radius="0.0108" length="0.0242"/>
            </geometry>
        </collision>
        <collision>
            <origin xyz="0 0 0.0108" rpy="0 0 0"/>
            <geometry>
                <sphere radius="0.0108"/>
            </geometry>
        </collision>
        <collision>
            <origin xyz="0 0 0.035" rpy="0 0 0"/>
            <geometry>
                <sphere radius="0.0108"/>
            </geometry>
        </collision>
    </link>

    <joint name="index_joint3" type="revolute">
        <parent link="index_proximal"/>
        <child link="index_middle"/>
        <origin xyz="0 0 0.0458" rpy="0 0 0"/> 
        <axis xyz="0 1 0"/>
        <limit lower="0.0" upper="0.0" effort="1.0" velocity="1.0"/>
    </joint>

    <link name="index_middle">
    </link>

    <joint name="index_joint4" type="revolute">
        <parent link="index_middle"/>
        <child link="index_distal"/>
        <origin xyz="0 0 0.0" rpy="0 0 0"/> 
        <axis xyz="0 1 0"/>
        <limit lower="0.0" upper="1.7453" effort="1.0" velocity="1.0"/>
    </joint>

    <link name="index_distal">
        <inertial>
            <origin xyz="0 0 0.025" rpy="0 0 0"/>
            <mass value="0.018321811200000003"/>
            <inertia ixx="4.351308014592001e-06" ixy="0.0" ixz="0.0" iyy="4.351308014592001e-06" iyz="0.0" izz="1.0685280291840003e-06"/>
        </inertial>
        <visual>
            <origin xyz="0 0 0.025" rpy="0 0 0"/>
            <geometry>
                <cylinder radius="0.0108" length="0.0284"/>
            </geometry>
            <material name="default"/>
        </visual>
        <visual>
            <origin xyz="0 0 0.0108" rpy="0 0 0"/>
            <geometry>
                <sphere radius="0.0108"/>
            </geometry>
            <material name="default"/>
        </visual>
        <visual>
            <origin xyz="0 0 0.0392" rpy="0 0 0"/>
            <geometry>
                <sphere radius="0.0108"/>
            </geometry>
            <material name="default"/>
        </visual>
        <collision>
            <origin xyz="0 0 0.025" rpy="0 0 0"/>
            <geometry>
                <cylinder radius="0.0108" length="0.0284"/>
            </geometry>
        </collision>
        <collision>
            <origin xyz="0 0 0.0108" rpy="0 0 0"/>
            <geometry>
                <sphere radius="0.0108"/>
            </geometry>
        </collision>
        <collision>
            <origin xyz="0 0 0.0392" rpy="0 0 0"/>
            <geometry>
                <sphere radius="0.0108"/>
            </geometry>
        </collision>
    </link>

    
    <joint name="middle_joint1" type="revolute">
        <parent link="palm"/>
        <child link="middle_knuckle"/>
        <origin xyz="-0.0016 -0.0285 0.0777" rpy="0 0 0"/>
        <axis xyz="1 0 0"/>
        <limit lower="0.0" upper="0.0" effort="1.0" velocity="1.0"/>
    </joint>

    <link name="middle_knuckle"></link>

    <joint name="middle_joint2" type="revolute">
        <parent link="middle_knuckle"/>
        <child link="middle_proximal"/>
        <origin xyz="0 0 0" rpy="0 0 0"/>
        <axis xyz="0 1 0"/>
        <limit lower="0.0" upper="1.5708" effort="1.0" velocity="1.0"/>
    </joint>

    <link name="middle_proximal">
        <inertial>
            <origin xyz="0 0 0.0229" rpy="0 0 0"/>
            <mass value="0.0167827790592"/>
            <inertia ixx="3.4230715595112964e-06" ixy="0.0" ixz="0.0" iyy="3.4230715595112964e-06" iyz="0.0" izz="9.787716747325442e-07"/>
        </inertial>
        <visual>
            <origin xyz="0 0 0.0229" rpy="0 0 0"/>
            <geometry>
                <cylinder radius="0.0108" length="0.0242"/>
            </geometry>
            <material name="default"/>
        </visual>
        <visual>
            <origin xyz="0 0 0.0108" rpy="0 0 0"/>
            <geometry>
                <sphere radius="0.0108"/>
            </geometry>
            <material name="default"/>
        </visual>
        <visual>
            <origin xyz="0 0 0.035" rpy="0 0 0"/>
            <geometry>
                <sphere radius="0.0108"/>
            </geometry>
            <material name="default"/>
        </visual>
        <collision>
            <origin xyz="0 0 0.0229" rpy="0 0 0"/>
            <geometry>
                <cylinder radius="0.0108" length="0.0242"/>
            </geometry>
        </collision>
        <collision>
            <origin xyz="0 0 0.0108" rpy="0 0 0"/>
            <geometry>
                <sphere radius="0.0108"/>
            </geometry>
        </collision>
        <collision>
            <origin xyz="0 0 0.035" rpy="0 0 0"/>
            <geometry>
                <sphere radius="0.0108"/>
            </geometry>
        </collision>
    </link>

    <joint name="middle_joint3" type="revolute">
        <parent link="middle_proximal"/>
        <child link="middle_middle"/>
        <origin xyz="0 0 0.0458" rpy="0 0 0"/> 
        <axis xyz="0 1 0"/>
        <limit lower="0.0" upper="0.0" effort="1.0" velocity="1.0"/>
    </joint>

    <link name="middle_middle">
    </link>

    <joint name="middle_joint4" type="revolute">
        <parent link="middle_middle"/>
        <child link="middle_distal"/>
        <origin xyz="0 0 0.0" rpy="0 0 0"/> 
        <axis xyz="0 1 0"/>
        <limit lower="0.0" upper="1.7453" effort="1.0" velocity="1.0"/>
    </joint>

    <link name="middle_distal">
        <inertial>
            <origin xyz="0 0 0.025" rpy="0 0 0"/>
            <mass value="0.018321811200000003"/>
            <inertia ixx="4.351308014592001e-06" ixy="0.0" ixz="0.0" iyy="4.351308014592001e-06" iyz="0.0" izz="1.0685280291840003e-06"/>
        </inertial>
        <visual>
            <origin xyz="0 0 0.025" rpy="0 0 0"/>
            <geometry>
                <cylinder radius="0.0108" length="0.0284"/>
            </geometry>
            <material name="default"/>
        </visual>
        <visual>
            <origin xyz="0 0 0.0108" rpy="0 0 0"/>
            <geometry>
                <sphere radius="0.0108"/>
            </geometry>
            <material name="default"/>
        </visual>
        <visual>
            <origin xyz="0 0 0.0392" rpy="0 0 0"/>
            <geometry>
                <sphere radius="0.0108"/>
            </geometry>
            <material name="default"/>
        </visual>
        <collision>
            <origin xyz="0 0 0.025" rpy="0 0 0"/>
            <geometry>
                <cylinder radius="0.0108" length="0.0284"/>
            </geometry>
        </collision>
        <collision>
            <origin xyz="0 0 0.0108" rpy="0 0 0"/>
            <geometry>
                <sphere radius="0.0108"/>
            </geometry>
        </collision>
        <collision>
            <origin xyz="0 0 0.0392" rpy="0 0 0"/>
            <geometry>
                <sphere radius="0.0108"/>
            </geometry>
        </collision>
    </link>

    
    <joint name="ring_joint1" type="revolute">
        <parent link="palm"/>
        <child link="ring_knuckle"/>
        <origin xyz="0.0 0.0 0.0" rpy="0 0 0"/>
        <axis xyz="1 0 0"/>
        <limit lower="0.0" upper="0.0" effort="1.0" velocity="1.0"/>
    </joint>

    <link name="ring_knuckle"></link>

    <joint name="ring_joint2" type="revolute">
        <parent link="ring_knuckle"/>
        <child link="ring_proximal"/>
        <origin xyz="0 0 0" rpy="0 0 0"/>
        <axis xyz="0 1 0"/>
        <limit lower="0.0" upper="0.0" effort="1.0" velocity="1.0"/>
    </joint>

    <link name="ring_proximal">
    </link>

    <joint name="ring_joint3" type="revolute">
        <parent link="ring_proximal"/>
        <child link="ring_middle"/>
        <origin xyz="0 0 0.0458" rpy="0 0 0"/> 
        <axis xyz="0 1 0"/>
        <limit lower="0.0" upper="0.0" effort="1.0" velocity="1.0"/>
    </joint>

    <link name="ring_middle">
    </link>

    <joint name="ring_joint4" type="revolute">
        <parent link="ring_middle"/>
        <child link="ring_distal"/>
        <origin xyz="0 0 0.0" rpy="0 0 0"/> 
        <axis xyz="0 1 0"/>
        <limit lower="0.0" upper="0.0" effort="1.0" velocity="1.0"/>
    </joint>

    <link name="ring_distal">
    </link>

    
    <joint name="little_joint0" type="revolute">
        <parent link="palm"/>
        <child link="little_base"/>
        <origin xyz="0.0 0.0 0.0" rpy="0.0 0.0 0.0"/>
        <axis xyz="0 1 0"/>
        <limit lower="0.0" upper="0.0" effort="1.0" velocity="1.0"/>
    </joint>

    <link name="little_base"></link>

    <joint name="little_joint1" type="revolute">
        <parent link="little_base"/>
        <child link="little_knuckle"/>
        <origin xyz="0.0 0.0 0.0" rpy="-0.0 -0.0 -0.0"/>
        <axis xyz="1 0 0"/>
        <limit lower="0.0" upper="0.0" effort="1.0" velocity="1.0"/>
    </joint>

    <link name="little_knuckle"></link>

    <joint name="little_joint2" type="revolute">
        <parent link="little_knuckle"/>
        <child link="little_proximal"/>
        <origin xyz="0 0 0" rpy="0 0 0"/>
        <axis xyz="0 1 0"/>
        <limit lower="0.0" upper="0.0" effort="1.0" velocity="1.0"/>
    </joint>

    <link name="little_proximal">
    </link>

    <joint name="little_joint3" type="revolute">
        <parent link="little_proximal"/>
        <child link="little_middle"/>
        <origin xyz="0 0 0.0458" rpy="0 0 0"/> 
        <axis xyz="0 1 0"/>
        <limit lower="0.0" upper="0.0" effort="1.0" velocity="1.0"/>
    </joint>

    <link name="little_middle">
    </link>

    <joint name="little_joint4" type="revolute">
        <parent link="little_middle"/>
        <child link="little_distal"/>
        <origin xyz="0 0 0.0" rpy="0 0 0"/> 
        <axis xyz="0 1 0"/>
        <limit lower="0.0" upper="0.0" effort="1.0" velocity="1.0"/>
    </joint>

    <link name="little_distal">
    </link>

</robot>