<?xml version="1.0"?>
<robot name="DexterousHand">
    <material name="default">
        <color rgba="0.4 0.75 1 0.6"/>
    </material>


    <link name="world"/>
    <joint name="world_to_palm" type="fixed">
        <parent link="world"/>
        <child link="palm"/>
        <origin xyz="0 0 0" rpy="0 0 0"/>
    </joint>
    <link name="palm">
        <inertial>
            <origin xyz="0 0 0.05" rpy="0 0 0"/>
            <mass value="0.15708000000000003"/>
            <inertia ixx="0.00019635000000000006" ixy="0.0" ixz="0.0" iyy="9.948400000000004e-05" iyz="0.0" izz="9.948400000000004e-05"/>
        </inertial>
        <visual>
            <origin xyz="0 0 0.05" rpy="1.5708 0 1.5708"/>
            <geometry>
                <cylinder radius="0.05" length="0.02"/>
            </geometry>
            <material name="default"/>
        </visual>
        <collision>
            <origin xyz="0 0 0.05" rpy="1.5708 0 1.5708"/>
            <geometry>
                <cylinder radius="0.05" length="0.02"/>
            </geometry>
        </collision>
    </link>

    
    <joint name="thumb_joint1" type="revolute">
        <parent link="palm"/>
        <child link="thumb_base"/>
        <origin xyz="0.0183 0.0324 0.0385" rpy="0.0155 1.5671 -0.0373"/>
        <axis xyz="-1.0 0.0 0.0"/>
        <limit lower="-0.349" upper="0.96" effort="1.0" velocity="1.0"/>
    </joint>

    <link name="thumb_base"></link>

    <joint name="thumb_joint2" type="revolute">
        <parent link="thumb_base"/>
        <child link="thumb_proximal"/>
        <origin xyz="0 0 0" rpy="0 0 0"/>
        <axis xyz="0.0 -1.0 0.0"/>
        <limit lower="0.0" upper="1.05" effort="1.0" velocity="1.0"/>
    </joint>

    <link name="thumb_proximal">
        <inertial>
            <origin xyz="0 0 0.02695" rpy="0 0 0"/>
            <mass value="0.016933224"/>
            <inertia ixx="4.522878241420001e-06" ixy="0.0" ixz="0.0" 
            iyy="4.522878241420001e-06" iyz="0.0" izz="8.466612e-07"/>
        </inertial>
        <visual>
            <origin xyz="0 0 0.02695" rpy="0 0 0"/>
            <geometry>
                <cylinder radius="0.01" length="0.0339"/>
            </geometry>
            <material name="default"/>
        </visual>
        <visual>
            <origin xyz="0 0 0.01" rpy="0 0 0"/>
            <geometry>
                <sphere radius="0.01"/>
            </geometry>
            <material name="default"/>
        </visual>
        <visual>
            <origin xyz="0 0 0.0439" rpy="0 0 0"/>
            <geometry>
                <sphere radius="0.01"/>
            </geometry>
            <material name="default"/>
        </visual>
        <collision>
            <origin xyz="0 0 0.02695" rpy="0 0 0"/>
            <geometry>
                <cylinder radius="0.01" length="0.0339"/>
            </geometry>
        </collision>
        <collision>
            <origin xyz="0 0 0.01" rpy="0 0 0"/>
            <geometry>
                <sphere radius="0.01"/>
            </geometry>
        </collision>
        <collision>
            <origin xyz="0 0 0.0439" rpy="0 0 0"/>
            <geometry>
                <sphere radius="0.01"/>
            </geometry>
        </collision>
    </link>

    <joint name="thumb_joint3" type="revolute">
        <parent link="thumb_proximal"/>
        <child link="thumb_knuckle"/>
        <origin xyz="0 0 0.0539" rpy="0 0 0"/> 
        <axis xyz="1 0 0"/>
        <limit lower="0.0" upper="0.0" effort="1.0" velocity="1.0"/>
    </joint>

    <link name="thumb_knuckle"></link>

    <joint name="thumb_joint4" type="revolute">
        <parent link="thumb_knuckle"/>
        <child link="thumb_middle"/>
        <origin xyz="0 0 0" rpy="0 0 0"/> 
        <axis xyz="0 1 0"/>
        <limit lower="0.0" upper="0.0" effort="1.0" velocity="1.0"/>
    </joint>

    <link name="thumb_middle">
    </link>

    <joint name="thumb_joint5" type="revolute">
        <parent link="thumb_middle"/>
        <child link="thumb_distal"/>
        <origin xyz="0 0 0" rpy="0 0 0"/> 
        <axis xyz="0 1 0"/>
        <limit lower="0.0" upper="1.57" effort="1.0" velocity="1.0"/>
    </joint>

    <link name="thumb_distal">
        <inertial>
            <origin xyz="0 0 0.0225" rpy="0 0 0"/>
            <mass value="0.014137199999999999"/>
            <inertia ixx="2.7390824999999994e-06" ixy="0.0" ixz="0.0" 
            iyy="2.7390824999999994e-06" iyz="0.0" izz="7.0686e-07"/>
        </inertial>
        <visual>
            <origin xyz="0 0 0.0225" rpy="0 0 0"/>
            <geometry>
                <cylinder radius="0.01" length="0.024999999999999998"/>
            </geometry>
            <material name="default"/>
        </visual>
        <visual>
            <origin xyz="0 0 0.01" rpy="0 0 0"/>
            <geometry>
                <sphere radius="0.01"/>
            </geometry>
            <material name="default"/>
        </visual>
        <visual>
            <origin xyz="0 0 0.034999999999999996" rpy="0 0 0"/>
            <geometry>
                <sphere radius="0.01"/>
            </geometry>
            <material name="default"/>
        </visual>
        <collision>
            <origin xyz="0 0 0.0225" rpy="0 0 0"/>
            <geometry>
                <cylinder radius="0.01" length="0.024999999999999998"/>
            </geometry>
        </collision>
        <collision>
            <origin xyz="0 0 0.01" rpy="0 0 0"/>
            <geometry>
                <sphere radius="0.01"/>
            </geometry>
        </collision>
        <collision>
            <origin xyz="0 0 0.034999999999999996" rpy="0 0 0"/>
            <geometry>
                <sphere radius="0.01"/>
            </geometry>
        </collision>
    </link>

    
    <joint name="index_joint1" type="revolute">
        <parent link="palm"/>
        <child link="index_knuckle"/>
        <origin xyz="0.0026 0.0279 0.101" rpy="0 0 0"/>
        <axis xyz="1 0 0"/>
        <limit lower="-0.262" upper="0.262" effort="1.0" velocity="1.0"/>
    </joint>

    <link name="index_knuckle"></link>

    <joint name="index_joint2" type="revolute">
        <parent link="index_knuckle"/>
        <child link="index_proximal"/>
        <origin xyz="0 0 0" rpy="0 0 0"/>
        <axis xyz="0 1 0"/>
        <limit lower="-0.349" upper="1.57" effort="1.0" velocity="1.0"/>
    </joint>

    <link name="index_proximal">
        <inertial>
            <origin xyz="0 0 0.0238" rpy="0 0 0"/>
            <mass value="0.014954016"/>
            <inertia ixx="3.1973680076800003e-06" ixy="0.0" ixz="0.0" 
            iyy="3.1973680076800003e-06" iyz="0.0" izz="7.477008000000001e-07"/>
        </inertial>
        <visual>
            <origin xyz="0 0 0.0238" rpy="0 0 0"/>
            <geometry>
                <cylinder radius="0.01" length="0.027600000000000003"/>
            </geometry>
            <material name="default"/>
        </visual>
        <visual>
            <origin xyz="0 0 0.01" rpy="0 0 0"/>
            <geometry>
                <sphere radius="0.01"/>
            </geometry>
            <material name="default"/>
        </visual>
        <visual>
            <origin xyz="0 0 0.0376" rpy="0 0 0"/>
            <geometry>
                <sphere radius="0.01"/>
            </geometry>
            <material name="default"/>
        </visual>
        <collision>
            <origin xyz="0 0 0.0238" rpy="0 0 0"/>
            <geometry>
                <cylinder radius="0.01" length="0.027600000000000003"/>
            </geometry>
        </collision>
        <collision>
            <origin xyz="0 0 0.01" rpy="0 0 0"/>
            <geometry>
                <sphere radius="0.01"/>
            </geometry>
        </collision>
        <collision>
            <origin xyz="0 0 0.0376" rpy="0 0 0"/>
            <geometry>
                <sphere radius="0.01"/>
            </geometry>
        </collision>
    </link>

    <joint name="index_joint3" type="revolute">
        <parent link="index_proximal"/>
        <child link="index_middle"/>
        <origin xyz="0 0 0.0476" rpy="0 0 0"/> 
        <axis xyz="0 1 0"/>
        <limit lower="0.0" upper="0.0" effort="1.0" velocity="1.0"/>
    </joint>

    <link name="index_middle">
    </link>

    <joint name="index_joint4" type="revolute">
        <parent link="index_middle"/>
        <child link="index_distal"/>
        <origin xyz="0 0 0" rpy="0 0 0"/> 
        <axis xyz="0 1 0"/>
        <limit lower="0.0" upper="1.57" effort="1.0" velocity="1.0"/>
    </joint>

    <link name="index_distal">
        <inertial>
            <origin xyz="0 0 0.0225" rpy="0 0 0"/>
            <mass value="0.014137199999999999"/>
            <inertia ixx="2.7390824999999994e-06" ixy="0.0" ixz="0.0" 
            iyy="2.7390824999999994e-06" iyz="0.0" izz="7.0686e-07"/>
        </inertial>
        <visual>
            <origin xyz="0 0 0.0225" rpy="0 0 0"/>
            <geometry>
                <cylinder radius="0.01" length="0.024999999999999998"/>
            </geometry>
            <material name="default"/>
        </visual>
        <visual>
            <origin xyz="0 0 0.01" rpy="0 0 0"/>
            <geometry>
                <sphere radius="0.01"/>
            </geometry>
            <material name="default"/>
        </visual>
        <visual>
            <origin xyz="0 0 0.034999999999999996" rpy="0 0 0"/>
            <geometry>
                <sphere radius="0.01"/>
            </geometry>
            <material name="default"/>
        </visual>
        <collision>
            <origin xyz="0 0 0.0225" rpy="0 0 0"/>
            <geometry>
                <cylinder radius="0.01" length="0.024999999999999998"/>
            </geometry>
        </collision>
        <collision>
            <origin xyz="0 0 0.01" rpy="0 0 0"/>
            <geometry>
                <sphere radius="0.01"/>
            </geometry>
        </collision>
        <collision>
            <origin xyz="0 0 0.034999999999999996" rpy="0 0 0"/>
            <geometry>
                <sphere radius="0.01"/>
            </geometry>
        </collision>
    </link>

    
    <joint name="middle_joint1" type="revolute">
        <parent link="palm"/>
        <child link="middle_knuckle"/>
        <origin xyz="0.0026 0.0057 0.105" rpy="0 0 0"/>
        <axis xyz="1 0 0"/>
        <limit lower="-0.314" upper="0.401" effort="1.0" velocity="1.0"/>
    </joint>

    <link name="middle_knuckle"></link>

    <joint name="middle_joint2" type="revolute">
        <parent link="middle_knuckle"/>
        <child link="middle_proximal"/>
        <origin xyz="0 0 0" rpy="0 0 0"/>
        <axis xyz="0 1 0"/>
        <limit lower="-0.349" upper="1.57" effort="1.0" velocity="1.0"/>
    </joint>

    <link name="middle_proximal">
        <inertial>
            <origin xyz="0 0 0.0238" rpy="0 0 0"/>
            <mass value="0.014954016"/>
            <inertia ixx="3.1973680076800003e-06" ixy="0.0" ixz="0.0" 
            iyy="3.1973680076800003e-06" iyz="0.0" izz="7.477008000000001e-07"/>
        </inertial>
        <visual>
            <origin xyz="0 0 0.0238" rpy="0 0 0"/>
            <geometry>
                <cylinder radius="0.01" length="0.027600000000000003"/>
            </geometry>
            <material name="default"/>
        </visual>
        <visual>
            <origin xyz="0 0 0.01" rpy="0 0 0"/>
            <geometry>
                <sphere radius="0.01"/>
            </geometry>
            <material name="default"/>
        </visual>
        <visual>
            <origin xyz="0 0 0.0376" rpy="0 0 0"/>
            <geometry>
                <sphere radius="0.01"/>
            </geometry>
            <material name="default"/>
        </visual>
        <collision>
            <origin xyz="0 0 0.0238" rpy="0 0 0"/>
            <geometry>
                <cylinder radius="0.01" length="0.027600000000000003"/>
            </geometry>
        </collision>
        <collision>
            <origin xyz="0 0 0.01" rpy="0 0 0"/>
            <geometry>
                <sphere radius="0.01"/>
            </geometry>
        </collision>
        <collision>
            <origin xyz="0 0 0.0376" rpy="0 0 0"/>
            <geometry>
                <sphere radius="0.01"/>
            </geometry>
        </collision>
    </link>

    <joint name="middle_joint3" type="revolute">
        <parent link="middle_proximal"/>
        <child link="middle_middle"/>
        <origin xyz="0 0 0.0476" rpy="0 0 0"/> 
        <axis xyz="0 1 0"/>
        <limit lower="0.0" upper="0.0" effort="1.0" velocity="1.0"/>
    </joint>

    <link name="middle_middle">
    </link>

    <joint name="middle_joint4" type="revolute">
        <parent link="middle_middle"/>
        <child link="middle_distal"/>
        <origin xyz="0 0 0" rpy="0 0 0"/> 
        <axis xyz="0 1 0"/>
        <limit lower="0.0" upper="1.57" effort="1.0" velocity="1.0"/>
    </joint>

    <link name="middle_distal">
        <inertial>
            <origin xyz="0 0 0.0225" rpy="0 0 0"/>
            <mass value="0.014137199999999999"/>
            <inertia ixx="2.7390824999999994e-06" ixy="0.0" ixz="0.0" 
            iyy="2.7390824999999994e-06" iyz="0.0" izz="7.0686e-07"/>
        </inertial>
        <visual>
            <origin xyz="0 0 0.0225" rpy="0 0 0"/>
            <geometry>
                <cylinder radius="0.01" length="0.024999999999999998"/>
            </geometry>
            <material name="default"/>
        </visual>
        <visual>
            <origin xyz="0 0 0.01" rpy="0 0 0"/>
            <geometry>
                <sphere radius="0.01"/>
            </geometry>
            <material name="default"/>
        </visual>
        <visual>
            <origin xyz="0 0 0.034999999999999996" rpy="0 0 0"/>
            <geometry>
                <sphere radius="0.01"/>
            </geometry>
            <material name="default"/>
        </visual>
        <collision>
            <origin xyz="0 0 0.0225" rpy="0 0 0"/>
            <geometry>
                <cylinder radius="0.01" length="0.024999999999999998"/>
            </geometry>
        </collision>
        <collision>
            <origin xyz="0 0 0.01" rpy="0 0 0"/>
            <geometry>
                <sphere radius="0.01"/>
            </geometry>
        </collision>
        <collision>
            <origin xyz="0 0 0.034999999999999996" rpy="0 0 0"/>
            <geometry>
                <sphere radius="0.01"/>
            </geometry>
        </collision>
    </link>

    
    <joint name="ring_joint1" type="revolute">
        <parent link="palm"/>
        <child link="ring_knuckle"/>
        <origin xyz="0.0026 -0.0163 0.098" rpy="0 0 0"/>
        <axis xyz="1 0 0"/>
        <limit lower="-0.175" upper="0.349" effort="1.0" velocity="1.0"/>
    </joint>

    <link name="ring_knuckle"></link>

    <joint name="ring_joint2" type="revolute">
        <parent link="ring_knuckle"/>
        <child link="ring_proximal"/>
        <origin xyz="0 0 0" rpy="0 0 0"/>
        <axis xyz="0 1 0"/>
        <limit lower="-0.349" upper="1.57" effort="1.0" velocity="1.0"/>
    </joint>

    <link name="ring_proximal">
        <inertial>
            <origin xyz="0 0 0.0238" rpy="0 0 0"/>
            <mass value="0.014954016"/>
            <inertia ixx="3.1973680076800003e-06" ixy="0.0" ixz="0.0" 
            iyy="3.1973680076800003e-06" iyz="0.0" izz="7.477008000000001e-07"/>
        </inertial>
        <visual>
            <origin xyz="0 0 0.0238" rpy="0 0 0"/>
            <geometry>
                <cylinder radius="0.01" length="0.027600000000000003"/>
            </geometry>
            <material name="default"/>
        </visual>
        <visual>
            <origin xyz="0 0 0.01" rpy="0 0 0"/>
            <geometry>
                <sphere radius="0.01"/>
            </geometry>
            <material name="default"/>
        </visual>
        <visual>
            <origin xyz="0 0 0.0376" rpy="0 0 0"/>
            <geometry>
                <sphere radius="0.01"/>
            </geometry>
            <material name="default"/>
        </visual>
        <collision>
            <origin xyz="0 0 0.0238" rpy="0 0 0"/>
            <geometry>
                <cylinder radius="0.01" length="0.027600000000000003"/>
            </geometry>
        </collision>
        <collision>
            <origin xyz="0 0 0.01" rpy="0 0 0"/>
            <geometry>
                <sphere radius="0.01"/>
            </geometry>
        </collision>
        <collision>
            <origin xyz="0 0 0.0376" rpy="0 0 0"/>
            <geometry>
                <sphere radius="0.01"/>
            </geometry>
        </collision>
    </link>

    <joint name="ring_joint3" type="revolute">
        <parent link="ring_proximal"/>
        <child link="ring_middle"/>
        <origin xyz="0 0 0.0476" rpy="0 0 0"/> 
        <axis xyz="0 1 0"/>
        <limit lower="0.0" upper="0.0" effort="1.0" velocity="1.0"/>
    </joint>

    <link name="ring_middle">
    </link>

    <joint name="ring_joint4" type="revolute">
        <parent link="ring_middle"/>
        <child link="ring_distal"/>
        <origin xyz="0 0 0" rpy="0 0 0"/> 
        <axis xyz="0 1 0"/>
        <limit lower="0.0" upper="1.57" effort="1.0" velocity="1.0"/>
    </joint>

    <link name="ring_distal">
        <inertial>
            <origin xyz="0 0 0.0225" rpy="0 0 0"/>
            <mass value="0.014137199999999999"/>
            <inertia ixx="2.7390824999999994e-06" ixy="0.0" ixz="0.0" 
            iyy="2.7390824999999994e-06" iyz="0.0" izz="7.0686e-07"/>
        </inertial>
        <visual>
            <origin xyz="0 0 0.0225" rpy="0 0 0"/>
            <geometry>
                <cylinder radius="0.01" length="0.024999999999999998"/>
            </geometry>
            <material name="default"/>
        </visual>
        <visual>
            <origin xyz="0 0 0.01" rpy="0 0 0"/>
            <geometry>
                <sphere radius="0.01"/>
            </geometry>
            <material name="default"/>
        </visual>
        <visual>
            <origin xyz="0 0 0.034999999999999996" rpy="0 0 0"/>
            <geometry>
                <sphere radius="0.01"/>
            </geometry>
            <material name="default"/>
        </visual>
        <collision>
            <origin xyz="0 0 0.0225" rpy="0 0 0"/>
            <geometry>
                <cylinder radius="0.01" length="0.024999999999999998"/>
            </geometry>
        </collision>
        <collision>
            <origin xyz="0 0 0.01" rpy="0 0 0"/>
            <geometry>
                <sphere radius="0.01"/>
            </geometry>
        </collision>
        <collision>
            <origin xyz="0 0 0.034999999999999996" rpy="0 0 0"/>
            <geometry>
                <sphere radius="0.01"/>
            </geometry>
        </collision>
    </link>

    
    <joint name="little_joint0" type="revolute">
        <parent link="palm"/>
        <child link="little_base"/>
        <origin xyz="0.0 0.0 0.0" rpy="0.0 0.0 0.0"/>
        <axis xyz="0 1 0"/>
        <limit lower="0.0" upper="0.0" effort="1.0" velocity="1.0"/>
    </joint>

    <link name="little_base"></link>

    <joint name="little_joint1" type="revolute">
        <parent link="little_base"/>
        <child link="little_knuckle"/>
        <origin xyz="0.0026 -0.0383 0.092" rpy="-0.0 -0.0 -0.0"/>
        <axis xyz="1 0 0"/>
        <limit lower="-0.105" upper="0.349" effort="1.0" velocity="1.0"/>
    </joint>

    <link name="little_knuckle"></link>

    <joint name="little_joint2" type="revolute">
        <parent link="little_knuckle"/>
        <child link="little_proximal"/>
        <origin xyz="0 0 0" rpy="0 0 0"/>
        <axis xyz="0 1 0"/>
        <limit lower="-0.349" upper="1.57" effort="1.0" velocity="1.0"/>
    </joint>

    <link name="little_proximal">
        <inertial>
            <origin xyz="0 0 0.0238" rpy="0 0 0"/>
            <mass value="0.014954016"/>
            <inertia ixx="3.1973680076800003e-06" ixy="0.0" ixz="0.0" 
            iyy="3.1973680076800003e-06" iyz="0.0" izz="7.477008000000001e-07"/>
        </inertial>
        <visual>
            <origin xyz="0 0 0.0238" rpy="0 0 0"/>
            <geometry>
                <cylinder radius="0.01" length="0.027600000000000003"/>
            </geometry>
            <material name="default"/>
        </visual>
        <visual>
            <origin xyz="0 0 0.01" rpy="0 0 0"/>
            <geometry>
                <sphere radius="0.01"/>
            </geometry>
            <material name="default"/>
        </visual>
        <visual>
            <origin xyz="0 0 0.0376" rpy="0 0 0"/>
            <geometry>
                <sphere radius="0.01"/>
            </geometry>
            <material name="default"/>
        </visual>
        <collision>
            <origin xyz="0 0 0.0238" rpy="0 0 0"/>
            <geometry>
                <cylinder radius="0.01" length="0.027600000000000003"/>
            </geometry>
        </collision>
        <collision>
            <origin xyz="0 0 0.01" rpy="0 0 0"/>
            <geometry>
                <sphere radius="0.01"/>
            </geometry>
        </collision>
        <collision>
            <origin xyz="0 0 0.0376" rpy="0 0 0"/>
            <geometry>
                <sphere radius="0.01"/>
            </geometry>
        </collision>
    </link>

    <joint name="little_joint3" type="revolute">
        <parent link="little_proximal"/>
        <child link="little_middle"/>
        <origin xyz="0 0 0.0476" rpy="0 0 0"/> 
        <axis xyz="0 1 0"/>
        <limit lower="0.0" upper="0.0" effort="1.0" velocity="1.0"/>
    </joint>

    <link name="little_middle">
    </link>

    <joint name="little_joint4" type="revolute">
        <parent link="little_middle"/>
        <child link="little_distal"/>
        <origin xyz="0 0 0" rpy="0 0 0"/> 
        <axis xyz="0 1 0"/>
        <limit lower="0.0" upper="1.57" effort="1.0" velocity="1.0"/>
    </joint>

    <link name="little_distal">
        <inertial>
            <origin xyz="0 0 0.0225" rpy="0 0 0"/>
            <mass value="0.014137199999999999"/>
            <inertia ixx="2.7390824999999994e-06" ixy="0.0" ixz="0.0" 
            iyy="2.7390824999999994e-06" iyz="0.0" izz="7.0686e-07"/>
        </inertial>
        <visual>
            <origin xyz="0 0 0.0225" rpy="0 0 0"/>
            <geometry>
                <cylinder radius="0.01" length="0.024999999999999998"/>
            </geometry>
            <material name="default"/>
        </visual>
        <visual>
            <origin xyz="0 0 0.01" rpy="0 0 0"/>
            <geometry>
                <sphere radius="0.01"/>
            </geometry>
            <material name="default"/>
        </visual>
        <visual>
            <origin xyz="0 0 0.034999999999999996" rpy="0 0 0"/>
            <geometry>
                <sphere radius="0.01"/>
            </geometry>
            <material name="default"/>
        </visual>
        <collision>
            <origin xyz="0 0 0.0225" rpy="0 0 0"/>
            <geometry>
                <cylinder radius="0.01" length="0.024999999999999998"/>
            </geometry>
        </collision>
        <collision>
            <origin xyz="0 0 0.01" rpy="0 0 0"/>
            <geometry>
                <sphere radius="0.01"/>
            </geometry>
        </collision>
        <collision>
            <origin xyz="0 0 0.034999999999999996" rpy="0 0 0"/>
            <geometry>
                <sphere radius="0.01"/>
            </geometry>
        </collision>
    </link>

</robot>